[2024-11-06T10:04:09.813+0000] {taskinstance.py:1171} INFO - Dependencies all met for <TaskInstance: marketstack_dag.validate_data scheduled__2024-11-05T00:00:00+00:00 [queued]>
[2024-11-06T10:04:09.819+0000] {taskinstance.py:1171} INFO - Dependencies all met for <TaskInstance: marketstack_dag.validate_data scheduled__2024-11-05T00:00:00+00:00 [queued]>
[2024-11-06T10:04:09.819+0000] {taskinstance.py:1368} INFO - 
--------------------------------------------------------------------------------
[2024-11-06T10:04:09.819+0000] {taskinstance.py:1369} INFO - Starting attempt 5 of 6
[2024-11-06T10:04:09.819+0000] {taskinstance.py:1370} INFO - 
--------------------------------------------------------------------------------
[2024-11-06T10:04:09.827+0000] {taskinstance.py:1389} INFO - Executing <Task(PythonOperator): validate_data> on 2024-11-05 00:00:00+00:00
[2024-11-06T10:04:09.830+0000] {standard_task_runner.py:52} INFO - Started process 1962 to run task
[2024-11-06T10:04:09.831+0000] {standard_task_runner.py:79} INFO - Running: ['***', 'tasks', 'run', 'marketstack_dag', 'validate_data', 'scheduled__2024-11-05T00:00:00+00:00', '--job-id', '47', '--raw', '--subdir', 'DAGS_FOLDER/stage.py', '--cfg-path', '/tmp/tmpepimyukd', '--error-file', '/tmp/tmpt_l71szz']
[2024-11-06T10:04:09.832+0000] {standard_task_runner.py:80} INFO - Job 47: Subtask validate_data
[2024-11-06T10:04:09.861+0000] {task_command.py:371} INFO - Running <TaskInstance: marketstack_dag.validate_data scheduled__2024-11-05T00:00:00+00:00 [running]> on host dd55d6bc6a7f
[2024-11-06T10:04:09.897+0000] {taskinstance.py:1583} INFO - Exporting the following env vars:
AIRFLOW_CTX_DAG_OWNER=***
AIRFLOW_CTX_DAG_ID=marketstack_dag
AIRFLOW_CTX_TASK_ID=validate_data
AIRFLOW_CTX_EXECUTION_DATE=2024-11-05T00:00:00+00:00
AIRFLOW_CTX_TRY_NUMBER=5
AIRFLOW_CTX_DAG_RUN_ID=scheduled__2024-11-05T00:00:00+00:00
[2024-11-06T10:04:09.904+0000] {base.py:68} INFO - Using connection ID 'datapstg' for task execution.
[2024-11-06T10:04:09.916+0000] {logging_mixin.py:115} INFO -    id ticker        date     open   close     high       low    volume
0   1   MSFT  2024-10-29  428.000  431.95  433.170  425.8001  17644080
1   2   AAPL  2024-10-29  233.100  233.67  234.325  232.3200  35417247
2   3  GOOGL  2024-10-29  167.730  169.68  170.380  167.0896  42169025
3   4   MSFT  2024-10-28  431.655  426.59  431.940  426.3400  14003953
4   5   AAPL  2024-10-28  233.315  233.40  234.730  232.5500  34733733
[2024-11-06T10:04:09.920+0000] {taskinstance.py:1902} ERROR - Task failed with exception
Traceback (most recent call last):
  File "/home/airflow/.local/lib/python3.7/site-packages/airflow/operators/python.py", line 171, in execute
    return_value = self.execute_callable()
  File "/home/airflow/.local/lib/python3.7/site-packages/airflow/operators/python.py", line 189, in execute_callable
    return self.python_callable(*self.op_args, **self.op_kwargs)
  File "/opt/airflow/dags/stage.py", line 81, in <lambda>
    python_callable=lambda: validate_data(),
  File "/opt/airflow/dags/stage.py", line 62, in validate_data
    assert stock_data[['ticker', 'date']].duplicated().sum() == 0, "Найдены дубликаты записей"
AssertionError: Найдены дубликаты записей
[2024-11-06T10:04:09.927+0000] {taskinstance.py:1412} INFO - Marking task as UP_FOR_RETRY. dag_id=marketstack_dag, task_id=validate_data, execution_date=20241105T000000, start_date=20241106T100409, end_date=20241106T100409
[2024-11-06T10:04:09.934+0000] {standard_task_runner.py:97} ERROR - Failed to execute job 47 for task validate_data (Найдены дубликаты записей; 1962)
[2024-11-06T10:04:09.963+0000] {local_task_job.py:156} INFO - Task exited with return code 1
[2024-11-06T10:04:09.995+0000] {local_task_job.py:279} INFO - 0 downstream tasks scheduled from follow-on schedule check
