[2024-11-06T10:01:16.720+0000] {taskinstance.py:1171} INFO - Dependencies all met for <TaskInstance: marketstack_dag.validate_data scheduled__2024-11-05T00:00:00+00:00 [queued]>
[2024-11-06T10:01:16.726+0000] {taskinstance.py:1171} INFO - Dependencies all met for <TaskInstance: marketstack_dag.validate_data scheduled__2024-11-05T00:00:00+00:00 [queued]>
[2024-11-06T10:01:16.726+0000] {taskinstance.py:1368} INFO - 
--------------------------------------------------------------------------------
[2024-11-06T10:01:16.726+0000] {taskinstance.py:1369} INFO - Starting attempt 3 of 4
[2024-11-06T10:01:16.727+0000] {taskinstance.py:1370} INFO - 
--------------------------------------------------------------------------------
[2024-11-06T10:01:16.734+0000] {taskinstance.py:1389} INFO - Executing <Task(PythonOperator): validate_data> on 2024-11-05 00:00:00+00:00
[2024-11-06T10:01:16.737+0000] {standard_task_runner.py:52} INFO - Started process 1811 to run task
[2024-11-06T10:01:16.738+0000] {standard_task_runner.py:79} INFO - Running: ['***', 'tasks', 'run', 'marketstack_dag', 'validate_data', 'scheduled__2024-11-05T00:00:00+00:00', '--job-id', '45', '--raw', '--subdir', 'DAGS_FOLDER/stage.py', '--cfg-path', '/tmp/tmpcb57zlgx', '--error-file', '/tmp/tmpwgq21adz']
[2024-11-06T10:01:16.739+0000] {standard_task_runner.py:80} INFO - Job 45: Subtask validate_data
[2024-11-06T10:01:16.769+0000] {task_command.py:371} INFO - Running <TaskInstance: marketstack_dag.validate_data scheduled__2024-11-05T00:00:00+00:00 [running]> on host dd55d6bc6a7f
[2024-11-06T10:01:16.806+0000] {taskinstance.py:1583} INFO - Exporting the following env vars:
AIRFLOW_CTX_DAG_OWNER=***
AIRFLOW_CTX_DAG_ID=marketstack_dag
AIRFLOW_CTX_TASK_ID=validate_data
AIRFLOW_CTX_EXECUTION_DATE=2024-11-05T00:00:00+00:00
AIRFLOW_CTX_TRY_NUMBER=3
AIRFLOW_CTX_DAG_RUN_ID=scheduled__2024-11-05T00:00:00+00:00
[2024-11-06T10:01:16.810+0000] {base.py:68} INFO - Using connection ID 'datapstg' for task execution.
[2024-11-06T10:01:16.816+0000] {taskinstance.py:1902} ERROR - Task failed with exception
Traceback (most recent call last):
  File "/home/airflow/.local/lib/python3.7/site-packages/airflow/operators/python.py", line 171, in execute
    return_value = self.execute_callable()
  File "/home/airflow/.local/lib/python3.7/site-packages/airflow/operators/python.py", line 189, in execute_callable
    return self.python_callable(*self.op_args, **self.op_kwargs)
  File "/opt/airflow/dags/stage.py", line 80, in <lambda>
    python_callable=lambda: validate_data(),
  File "/opt/airflow/dags/stage.py", line 55, in validate_data
    assert stock_data[['symbol', 'date', 'open', 'close', 'high', 'low', 'volume']].notnull().all().all(), "Найдены пустые значения"
  File "/home/airflow/.local/lib/python3.7/site-packages/pandas/core/frame.py", line 3464, in __getitem__
    indexer = self.loc._get_listlike_indexer(key, axis=1)[1]
  File "/home/airflow/.local/lib/python3.7/site-packages/pandas/core/indexing.py", line 1314, in _get_listlike_indexer
    self._validate_read_indexer(keyarr, indexer, axis)
  File "/home/airflow/.local/lib/python3.7/site-packages/pandas/core/indexing.py", line 1377, in _validate_read_indexer
    raise KeyError(f"{not_found} not in index")
KeyError: "['symbol'] not in index"
[2024-11-06T10:01:16.824+0000] {taskinstance.py:1412} INFO - Marking task as UP_FOR_RETRY. dag_id=marketstack_dag, task_id=validate_data, execution_date=20241105T000000, start_date=20241106T100116, end_date=20241106T100116
[2024-11-06T10:01:16.830+0000] {standard_task_runner.py:97} ERROR - Failed to execute job 45 for task validate_data ("['symbol'] not in index"; 1811)
[2024-11-06T10:01:16.870+0000] {local_task_job.py:156} INFO - Task exited with return code 1
[2024-11-06T10:01:16.886+0000] {local_task_job.py:279} INFO - 0 downstream tasks scheduled from follow-on schedule check
