[2024-11-06T10:03:16.505+0000] {taskinstance.py:1171} INFO - Dependencies all met for <TaskInstance: marketstack_dag.validate_data scheduled__2024-11-05T00:00:00+00:00 [queued]>
[2024-11-06T10:03:16.511+0000] {taskinstance.py:1171} INFO - Dependencies all met for <TaskInstance: marketstack_dag.validate_data scheduled__2024-11-05T00:00:00+00:00 [queued]>
[2024-11-06T10:03:16.511+0000] {taskinstance.py:1368} INFO - 
--------------------------------------------------------------------------------
[2024-11-06T10:03:16.511+0000] {taskinstance.py:1369} INFO - Starting attempt 4 of 5
[2024-11-06T10:03:16.511+0000] {taskinstance.py:1370} INFO - 
--------------------------------------------------------------------------------
[2024-11-06T10:03:16.519+0000] {taskinstance.py:1389} INFO - Executing <Task(PythonOperator): validate_data> on 2024-11-05 00:00:00+00:00
[2024-11-06T10:03:16.522+0000] {standard_task_runner.py:52} INFO - Started process 1914 to run task
[2024-11-06T10:03:16.523+0000] {standard_task_runner.py:79} INFO - Running: ['***', 'tasks', 'run', 'marketstack_dag', 'validate_data', 'scheduled__2024-11-05T00:00:00+00:00', '--job-id', '46', '--raw', '--subdir', 'DAGS_FOLDER/stage.py', '--cfg-path', '/tmp/tmp58civohm', '--error-file', '/tmp/tmp9pj571yt']
[2024-11-06T10:03:16.524+0000] {standard_task_runner.py:80} INFO - Job 46: Subtask validate_data
[2024-11-06T10:03:16.558+0000] {task_command.py:371} INFO - Running <TaskInstance: marketstack_dag.validate_data scheduled__2024-11-05T00:00:00+00:00 [running]> on host dd55d6bc6a7f
[2024-11-06T10:03:16.605+0000] {taskinstance.py:1583} INFO - Exporting the following env vars:
AIRFLOW_CTX_DAG_OWNER=***
AIRFLOW_CTX_DAG_ID=marketstack_dag
AIRFLOW_CTX_TASK_ID=validate_data
AIRFLOW_CTX_EXECUTION_DATE=2024-11-05T00:00:00+00:00
AIRFLOW_CTX_TRY_NUMBER=4
AIRFLOW_CTX_DAG_RUN_ID=scheduled__2024-11-05T00:00:00+00:00
[2024-11-06T10:03:16.612+0000] {base.py:68} INFO - Using connection ID 'datapstg' for task execution.
[2024-11-06T10:03:16.631+0000] {logging_mixin.py:115} INFO -    id ticker        date     open   close     high       low    volume
0   1   MSFT  2024-10-29  428.000  431.95  433.170  425.8001  17644080
1   2   AAPL  2024-10-29  233.100  233.67  234.325  232.3200  35417247
2   3  GOOGL  2024-10-29  167.730  169.68  170.380  167.0896  42169025
3   4   MSFT  2024-10-28  431.655  426.59  431.940  426.3400  14003953
4   5   AAPL  2024-10-28  233.315  233.40  234.730  232.5500  34733733
[2024-11-06T10:03:16.632+0000] {taskinstance.py:1902} ERROR - Task failed with exception
Traceback (most recent call last):
  File "/home/airflow/.local/lib/python3.7/site-packages/airflow/operators/python.py", line 171, in execute
    return_value = self.execute_callable()
  File "/home/airflow/.local/lib/python3.7/site-packages/airflow/operators/python.py", line 189, in execute_callable
    return self.python_callable(*self.op_args, **self.op_kwargs)
  File "/opt/airflow/dags/stage.py", line 81, in <lambda>
    python_callable=lambda: validate_data(),
  File "/opt/airflow/dags/stage.py", line 56, in validate_data
    assert stock_data[['symbol', 'date', 'open', 'close', 'high', 'low', 'volume']].notnull().all().all(), "Найдены пустые значения"
  File "/home/airflow/.local/lib/python3.7/site-packages/pandas/core/frame.py", line 3464, in __getitem__
    indexer = self.loc._get_listlike_indexer(key, axis=1)[1]
  File "/home/airflow/.local/lib/python3.7/site-packages/pandas/core/indexing.py", line 1314, in _get_listlike_indexer
    self._validate_read_indexer(keyarr, indexer, axis)
  File "/home/airflow/.local/lib/python3.7/site-packages/pandas/core/indexing.py", line 1377, in _validate_read_indexer
    raise KeyError(f"{not_found} not in index")
KeyError: "['symbol'] not in index"
[2024-11-06T10:03:16.640+0000] {taskinstance.py:1412} INFO - Marking task as UP_FOR_RETRY. dag_id=marketstack_dag, task_id=validate_data, execution_date=20241105T000000, start_date=20241106T100316, end_date=20241106T100316
[2024-11-06T10:03:16.647+0000] {standard_task_runner.py:97} ERROR - Failed to execute job 46 for task validate_data ("['symbol'] not in index"; 1914)
[2024-11-06T10:03:16.655+0000] {local_task_job.py:156} INFO - Task exited with return code 1
[2024-11-06T10:03:16.675+0000] {local_task_job.py:279} INFO - 0 downstream tasks scheduled from follow-on schedule check
